<?xml version="1.0" ?>
<!-- =================================================================================== -->
<!-- |    This document was autogenerated by xacro from crane_plus.urdf.xacro          | -->
<!-- |    EDITING THIS FILE BY HAND IS NOT RECOMMENDED                                 | -->
<!-- =================================================================================== -->
<robot name="crane_plus" xmlns:controller="http://playerstage.sourceforge.net/gazebo/xmlschema/#controller" xmlns:interface="http://playerstage.sourceforge.net/gazebo/xmlschema/#interface" xmlns:sensor="http://playerstage.sourceforge.net/gazebo/xmlschema/#sensor">
  <material name="black">
    <color rgba="0.2 0.2 0.2 1.0"/>
  </material>
  <material name="white">
    <color rgba="0.95 0.95 0.95 1.0"/>
  </material>
  <material name="silver">
    <color rgba="0.75 0.75 0.75 1.0"/>
  </material>
  <material name="red">
    <color rgba="1.0 0.3 0.3 1.0"/>
  </material>
  <material name="green">
    <color rgba="0.3 1.0 0.3 1.0"/>
  </material>
  <material name="blue">
    <color rgba="0.3 0.3 1.0 1.0"/>
  </material>
  <!-- Link to provide the location reference for the arm -->
  <link name="base_link"/>
  <!-- Used for fixing robot to Gazebo 'base_link' -->
  <link name="world"/>
  <joint name="base_link_to_world_joint" type="fixed">
    <parent link="world"/>
    <child link="base_link"/>
  </joint>
  <joint name="crane_plus_joint_base" type="fixed">
    <origin xyz="0 0 0"/>
    <parent link="base_link"/>
    <child link="crane_plus_base"/>
  </joint>
  <link name="crane_plus_base">
    <visual>
      <origin rpy="0 0 0" xyz="0 0 0"/>
      <geometry>
        <mesh filename="package://crane_plus_description/meshes/visual/body_20201013.stl" scale="1 1 1"/>
      </geometry>
      <material name="black"/>
    </visual>
    <collision>
      <origin rpy="0 0 0" xyz="0 0 0"/>
      <geometry>
        <mesh filename="package://crane_plus_description/meshes/collision/body_collision_20201013.stl" scale="1 1 1"/>
      </geometry>
      <material name="black"/>
    </collision>
    <inertial>
      <mass value="0.06645"/>
      <origin rpy="0 0.39269875 0" xyz="-1.31E-02 7.00E-06 2.12E-02"/>
      <inertia ixx="1.66E-05" ixy="1.80E-09" ixz="-5.75E-07" iyy="2.36E-05" iyz="-3.23E-08" izz="1.77E-05"/>
    </inertial>
  </link>
  <joint name="crane_plus_joint1" type="revolute">
    <origin rpy="0 0 0" xyz="0 0 0.0454"/>
    <axis xyz="0 0 1"/>
    <limit effort="1.5" lower="-2.6179916666666663" upper="2.6179916666666663" velocity="2.0"/>
    <parent link="crane_plus_base"/>
    <child link="crane_plus_link1"/>
    <dynamics damping="1.0e-6" friction="2.0e-1"/>
  </joint>
  <link name="crane_plus_link1">
    <visual>
      <origin rpy="0 0 3.14159" xyz="0 0 0"/>
      <geometry>
        <mesh filename="package://crane_plus_description/meshes/visual/Link1_20201013.stl" scale="1 1 1"/>
      </geometry>
      <material name="white"/>
    </visual>
    <collision>
      <origin rpy="0 0 3.14159" xyz="0 0 0"/>
      <geometry>
        <mesh filename="package://crane_plus_description/meshes/collision/Link1_collision_20201013.stl" scale="1 1 1"/>
      </geometry>
      <material name="white"/>
    </collision>
    <inertial>
      <mass value="0.007729"/>
      <origin rpy="0 0 0" xyz="2.00E-06 0.0 1.09E-02"/>
      <inertia ixx="3.43E-06" ixy="0.0" ixz="1.66E-10" iyy="1.30E-06" iyz="0.0" izz="3.05E-06"/>
    </inertial>
  </link>
  <joint name="crane_plus_joint2" type="revolute">
    <origin rpy="0 0 0" xyz="0 0 0.026"/>
    <axis xyz="0 1 0"/>
    <limit effort="1.5" lower="-1.8247401916666663" upper="1.7837249888888889" velocity="2.0"/>
    <parent link="crane_plus_link1"/>
    <child link="crane_plus_link2"/>
    <dynamics damping="1.0e-6" friction="2.0e-1"/>
  </joint>
  <link name="crane_plus_link2">
    <visual>
      <origin rpy="1.570795 0 0" xyz="0 0 0"/>
      <geometry>
        <mesh filename="package://crane_plus_description/meshes/visual/Link2_20201013.stl" scale="1 1 1"/>
      </geometry>
      <material name="black"/>
    </visual>
    <collision>
      <origin rpy="1.570795 0 0" xyz="0 0 0"/>
      <geometry>
        <mesh filename="package://crane_plus_description/meshes/collision/Link2_collision_20201013.stl" scale="1 1 1"/>
      </geometry>
      <material name="black"/>
    </collision>
    <inertial>
      <mass value="0.116745"/>
      <origin rpy="1.570795 0 0" xyz="7.99E-04 1.00E-06 4.15E-02"/>
      <inertia ixx="1.25E-04" ixy="6.83E-08" ixz="9.50E-11" iyy="1.92E-05" iyz="0.0" izz="1.19E-04"/>
    </inertial>
  </link>
  <joint name="crane_plus_joint3" type="revolute">
    <origin rpy="0 0 0" xyz="0 0 0.083"/>
    <axis xyz="0 -1 0"/>
    <limit effort="1.5" lower="-2.5565561288888885" upper="2.454279921111111" velocity="2.0"/>
    <parent link="crane_plus_link2"/>
    <child link="crane_plus_link3"/>
    <dynamics damping="1.0e-6" friction="2.0e-1"/>
  </joint>
  <link name="crane_plus_link3">
    <visual>
      <origin rpy="1.570795 0 0" xyz="0 0 0"/>
      <geometry>
        <mesh filename="package://crane_plus_description/meshes/visual/Link3_20201013.stl" scale="1 1 1"/>
      </geometry>
      <material name="white"/>
    </visual>
    <collision>
      <origin rpy="1.570795 0 0" xyz="0 0 0"/>
      <geometry>
        <mesh filename="package://crane_plus_description/meshes/collision/Link3_collision_20201013.stl" scale="1 1 1"/>
      </geometry>
      <material name="white"/>
    </collision>
    <inertial>
      <mass value="0.072317"/>
      <origin rpy="1.570795 0 0" xyz="6.45E-04 -1.38E-04 7.01E-02"/>
      <inertia ixx="5.41E-05" ixy="-2.28E-07" ixz="-2.67E-09" iyy="1.60E-05" iyz="-5.35E-07" izz="4.69E-05"/>
    </inertial>
  </link>
  <joint name="crane_plus_joint4" type="revolute">
    <origin rpy="0 0 0" xyz="0 0 0.0935"/>
    <axis xyz="0 -1 0"/>
    <limit effort="1.5" lower="-1.8400990761111107" upper="1.768366104444444" velocity="2.0"/>
    <parent link="crane_plus_link3"/>
    <child link="crane_plus_link4"/>
    <dynamics damping="1.0e-6" friction="2.0e-1"/>
  </joint>
  <link name="crane_plus_link4">
    <visual>
      <origin rpy="1.570795 0 0" xyz="0 0 0"/>
      <geometry>
        <mesh filename="package://crane_plus_description/meshes/visual/Link4_20201013.stl" scale="1 1 1"/>
      </geometry>
      <material name="black"/>
    </visual>
    <collision>
      <origin rpy="1.570795 0 0" xyz="0 0 0"/>
      <geometry>
        <mesh filename="package://crane_plus_description/meshes/collision/Link4_collision_20201013.stl" scale="1 1 1"/>
      </geometry>
      <material name="black"/>
    </collision>
    <inertial>
      <mass value="0.08185"/>
      <origin rpy="1.570795 0 0" xyz="6.45E-04 -5.70E-04 4.62E-02"/>
      <inertia ixx="5.91E-05" ixy="-5.11E-08" ixz="3.49E-07" iyy="3.62E-05" iyz="1.37E-05" izz="3.98E-05"/>
    </inertial>
  </link>
  <joint name="crane_plus_joint_hand" type="revolute">
    <origin rpy="0 0 0" xyz="0 -0.0145 0.045"/>
    <axis xyz="-1 0 0"/>
    <limit effort="1.5" lower="-0.7089521433333332" upper="0.6679369405555557" velocity="2.0"/>
    <parent link="crane_plus_link4"/>
    <child link="crane_plus_link_hand"/>
    <dynamics damping="1.0e-6" friction="2.0e-1"/>
  </joint>
  <link name="crane_plus_link_hand">
    <visual>
      <origin rpy="0 -1.570795 0" xyz="0 0 0"/>
      <geometry>
        <mesh filename="package://crane_plus_description/meshes/visual/Hand_20201013.stl" scale="1 1 1"/>
      </geometry>
      <material name="white"/>
    </visual>
    <collision>
      <origin rpy="0 -1.570795 0" xyz="0 0 0"/>
      <geometry>
        <mesh filename="package://crane_plus_description/meshes/collision/Hand_collision_20201013.stl" scale="1 1 1"/>
      </geometry>
      <material name="white"/>
    </collision>
    <inertial>
      <mass value="0.022901"/>
      <origin rpy="0 1.570795 0" xyz="0.0 -2.04E-02 2.77E-02"/>
      <inertia ixx="5.76E-06" ixy="-4.66E-07" ixz="0.0" iyy="2.76E-05" iyz="0.0" izz="2.52E-05"/>
    </inertial>
  </link>
  <ros2_control name="crane_plus" type="system">
    <hardware>
      <plugin>crane_plus_hardware/CranePlusHardware</plugin>
      <param name="port_name">/dev/ttyUSB0</param>
      <param name="baudrate">1000000</param>
      <param name="timeout_seconds">5.0</param>
      <param name="read_velocities">0</param>
      <param name="read_loads">0</param>
      <param name="read_voltages">0</param>
      <param name="read_temperatures">0</param>
    </hardware>
    <joint name="crane_plus_joint1">
      <command_interface name="position">
        <param name="min">-2.6179916666666663</param>
        <param name="max">2.6179916666666663</param>
      </command_interface>
      <state_interface name="position"/>
      <state_interface name="velocity"/>
      <state_interface name="load"/>
      <state_interface name="voltage"/>
      <state_interface name="temperature"/>
      <param name="dxl_id">1</param>
    </joint>
    <joint name="crane_plus_joint2">
      <command_interface name="position">
        <param name="min">-1.8247401916666663</param>
        <param name="max">1.7837249888888889</param>
      </command_interface>
      <state_interface name="position"/>
      <state_interface name="velocity"/>
      <state_interface name="load"/>
      <state_interface name="voltage"/>
      <state_interface name="temperature"/>
      <param name="dxl_id">2</param>
    </joint>
    <joint name="crane_plus_joint3">
      <command_interface name="position">
        <param name="min">-2.5565561288888885</param>
        <param name="max">2.454279921111111</param>
      </command_interface>
      <state_interface name="position"/>
      <state_interface name="velocity"/>
      <state_interface name="load"/>
      <state_interface name="voltage"/>
      <state_interface name="temperature"/>
      <param name="dxl_id">3</param>
    </joint>
    <joint name="crane_plus_joint4">
      <command_interface name="position">
        <param name="min">-1.8400990761111107</param>
        <param name="max">1.768366104444444</param>
      </command_interface>
      <state_interface name="position"/>
      <state_interface name="velocity"/>
      <state_interface name="load"/>
      <state_interface name="voltage"/>
      <state_interface name="temperature"/>
      <param name="dxl_id">4</param>
    </joint>
    <joint name="crane_plus_joint_hand">
      <command_interface name="position">
        <param name="min">-0.7089521433333332</param>
        <param name="max">0.6679369405555557</param>
      </command_interface>
      <state_interface name="position"/>
      <state_interface name="velocity"/>
      <state_interface name="load"/>
      <state_interface name="voltage"/>
      <state_interface name="temperature"/>
      <param name="dxl_id">5</param>
    </joint>
  </ros2_control>
</robot>
